I'm sorry, but an uncaught exception occurred.

While running game code:
  File "game/script.rpy", line 1359, in script
    python:
  File "game/script.rpy", line 1371, in <module>
    renpy.say(d,"[fortune]")
TypeError: 'bool' object is not callable

-- Full Traceback ------------------------------------------------------------

Full traceback:
  File "game/script.rpy", line 1359, in script
    python:
  File "C:\Users\User\Desktop\3\game-dev\renpy-8.1.0-sdk\renpy\ast.py", line 1138, in execute
    renpy.python.py_exec_bytecode(self.code.bytecode, self.hide, store=self.store)
  File "C:\Users\User\Desktop\3\game-dev\renpy-8.1.0-sdk\renpy\python.py", line 1122, in py_exec_bytecode
    exec(bytecode, globals, locals)
  File "game/script.rpy", line 1371, in <module>
    renpy.say(d,"[fortune]")
  File "C:\Users\User\Desktop\3\game-dev\renpy-8.1.0-sdk\renpy\exports.py", line 1473, in say
    who(what, *args, **kwargs)
TypeError: 'bool' object is not callable

Windows-8.1-6.3.9600 AMD64
Ren'Py 8.1.0.23051307
Fantasy Ren'py GUI template 1.0
Mon Jun  5 07:44:32 2023
